{
 "cells": [
  {
   "cell_type": "code",
   "execution_count": 11,
   "metadata": {},
   "outputs": [
    {
     "name": "stdout",
     "output_type": "stream",
     "text": [
      " * Serving Flask app \"__main__\" (lazy loading)\n",
      " * Environment: production\n",
      "   WARNING: This is a development server. Do not use it in a production deployment.\n",
      "   Use a production WSGI server instead.\n",
      " * Debug mode: off\n"
     ]
    },
    {
     "name": "stderr",
     "output_type": "stream",
     "text": [
      " * Running on http://127.0.0.1:5003/ (Press CTRL+C to quit)\n",
      "INFO:werkzeug: * Running on http://127.0.0.1:5003/ (Press CTRL+C to quit)\n",
      "[2020-11-23 18:07:46,785] ERROR in app: Exception on /predict [POST]\n",
      "Traceback (most recent call last):\n",
      "  File \"C:\\ProgramData\\Anaconda3\\envs\\deepkeras\\lib\\site-packages\\flask\\app.py\", line 2447, in wsgi_app\n",
      "    response = self.full_dispatch_request()\n",
      "  File \"C:\\ProgramData\\Anaconda3\\envs\\deepkeras\\lib\\site-packages\\flask\\app.py\", line 1952, in full_dispatch_request\n",
      "    rv = self.handle_user_exception(e)\n",
      "  File \"C:\\ProgramData\\Anaconda3\\envs\\deepkeras\\lib\\site-packages\\flask\\app.py\", line 1821, in handle_user_exception\n",
      "    reraise(exc_type, exc_value, tb)\n",
      "  File \"C:\\ProgramData\\Anaconda3\\envs\\deepkeras\\lib\\site-packages\\flask\\_compat.py\", line 39, in reraise\n",
      "    raise value\n",
      "  File \"C:\\ProgramData\\Anaconda3\\envs\\deepkeras\\lib\\site-packages\\flask\\app.py\", line 1950, in full_dispatch_request\n",
      "    rv = self.dispatch_request()\n",
      "  File \"C:\\ProgramData\\Anaconda3\\envs\\deepkeras\\lib\\site-packages\\flask\\app.py\", line 1936, in dispatch_request\n",
      "    return self.view_functions[rule.endpoint](**req.view_args)\n",
      "  File \"<ipython-input-11-0326dafe1a7e>\", line 42, in predictions\n",
      "    prediction = classifire.predict([[data]])[0]\n",
      "  File \"C:\\ProgramData\\Anaconda3\\envs\\deepkeras\\lib\\site-packages\\keras\\engine\\training.py\", line 1441, in predict\n",
      "    x, _, _ = self._standardize_user_data(x)\n",
      "  File \"C:\\ProgramData\\Anaconda3\\envs\\deepkeras\\lib\\site-packages\\keras\\engine\\training.py\", line 579, in _standardize_user_data\n",
      "    exception_prefix='input')\n",
      "  File \"C:\\ProgramData\\Anaconda3\\envs\\deepkeras\\lib\\site-packages\\keras\\engine\\training_utils.py\", line 145, in standardize_input_data\n",
      "    str(data_shape))\n",
      "ValueError: Error when checking input: expected dense_41_input to have shape (2,) but got array with shape (1,)\n",
      "ERROR:__main__:Exception on /predict [POST]\n",
      "Traceback (most recent call last):\n",
      "  File \"C:\\ProgramData\\Anaconda3\\envs\\deepkeras\\lib\\site-packages\\flask\\app.py\", line 2447, in wsgi_app\n",
      "    response = self.full_dispatch_request()\n",
      "  File \"C:\\ProgramData\\Anaconda3\\envs\\deepkeras\\lib\\site-packages\\flask\\app.py\", line 1952, in full_dispatch_request\n",
      "    rv = self.handle_user_exception(e)\n",
      "  File \"C:\\ProgramData\\Anaconda3\\envs\\deepkeras\\lib\\site-packages\\flask\\app.py\", line 1821, in handle_user_exception\n",
      "    reraise(exc_type, exc_value, tb)\n",
      "  File \"C:\\ProgramData\\Anaconda3\\envs\\deepkeras\\lib\\site-packages\\flask\\_compat.py\", line 39, in reraise\n",
      "    raise value\n",
      "  File \"C:\\ProgramData\\Anaconda3\\envs\\deepkeras\\lib\\site-packages\\flask\\app.py\", line 1950, in full_dispatch_request\n",
      "    rv = self.dispatch_request()\n",
      "  File \"C:\\ProgramData\\Anaconda3\\envs\\deepkeras\\lib\\site-packages\\flask\\app.py\", line 1936, in dispatch_request\n",
      "    return self.view_functions[rule.endpoint](**req.view_args)\n",
      "  File \"<ipython-input-11-0326dafe1a7e>\", line 42, in predictions\n",
      "    prediction = classifire.predict([[data]])[0]\n",
      "  File \"C:\\ProgramData\\Anaconda3\\envs\\deepkeras\\lib\\site-packages\\keras\\engine\\training.py\", line 1441, in predict\n",
      "    x, _, _ = self._standardize_user_data(x)\n",
      "  File \"C:\\ProgramData\\Anaconda3\\envs\\deepkeras\\lib\\site-packages\\keras\\engine\\training.py\", line 579, in _standardize_user_data\n",
      "    exception_prefix='input')\n",
      "  File \"C:\\ProgramData\\Anaconda3\\envs\\deepkeras\\lib\\site-packages\\keras\\engine\\training_utils.py\", line 145, in standardize_input_data\n",
      "    str(data_shape))\n",
      "ValueError: Error when checking input: expected dense_41_input to have shape (2,) but got array with shape (1,)\n",
      "127.0.0.1 - - [23/Nov/2020 18:07:46] \"\u001b[35m\u001b[1mPOST /predict HTTP/1.1\u001b[0m\" 500 -\n",
      "INFO:werkzeug:127.0.0.1 - - [23/Nov/2020 18:07:46] \"\u001b[35m\u001b[1mPOST /predict HTTP/1.1\u001b[0m\" 500 -\n"
     ]
    },
    {
     "name": "stdout",
     "output_type": "stream",
     "text": [
      "\n"
     ]
    },
    {
     "name": "stderr",
     "output_type": "stream",
     "text": [
      "[2020-11-23 18:08:04,304] ERROR in app: Exception on /predict [POST]\n",
      "Traceback (most recent call last):\n",
      "  File \"C:\\ProgramData\\Anaconda3\\envs\\deepkeras\\lib\\site-packages\\flask\\app.py\", line 2447, in wsgi_app\n",
      "    response = self.full_dispatch_request()\n",
      "  File \"C:\\ProgramData\\Anaconda3\\envs\\deepkeras\\lib\\site-packages\\flask\\app.py\", line 1952, in full_dispatch_request\n",
      "    rv = self.handle_user_exception(e)\n",
      "  File \"C:\\ProgramData\\Anaconda3\\envs\\deepkeras\\lib\\site-packages\\flask\\app.py\", line 1821, in handle_user_exception\n",
      "    reraise(exc_type, exc_value, tb)\n",
      "  File \"C:\\ProgramData\\Anaconda3\\envs\\deepkeras\\lib\\site-packages\\flask\\_compat.py\", line 39, in reraise\n",
      "    raise value\n",
      "  File \"C:\\ProgramData\\Anaconda3\\envs\\deepkeras\\lib\\site-packages\\flask\\app.py\", line 1950, in full_dispatch_request\n",
      "    rv = self.dispatch_request()\n",
      "  File \"C:\\ProgramData\\Anaconda3\\envs\\deepkeras\\lib\\site-packages\\flask\\app.py\", line 1936, in dispatch_request\n",
      "    return self.view_functions[rule.endpoint](**req.view_args)\n",
      "  File \"<ipython-input-11-0326dafe1a7e>\", line 42, in predictions\n",
      "    prediction = classifire.predict([[data]])[0]\n",
      "  File \"C:\\ProgramData\\Anaconda3\\envs\\deepkeras\\lib\\site-packages\\keras\\engine\\training.py\", line 1441, in predict\n",
      "    x, _, _ = self._standardize_user_data(x)\n",
      "  File \"C:\\ProgramData\\Anaconda3\\envs\\deepkeras\\lib\\site-packages\\keras\\engine\\training.py\", line 579, in _standardize_user_data\n",
      "    exception_prefix='input')\n",
      "  File \"C:\\ProgramData\\Anaconda3\\envs\\deepkeras\\lib\\site-packages\\keras\\engine\\training_utils.py\", line 145, in standardize_input_data\n",
      "    str(data_shape))\n",
      "ValueError: Error when checking input: expected dense_41_input to have shape (2,) but got array with shape (1,)\n",
      "ERROR:__main__:Exception on /predict [POST]\n",
      "Traceback (most recent call last):\n",
      "  File \"C:\\ProgramData\\Anaconda3\\envs\\deepkeras\\lib\\site-packages\\flask\\app.py\", line 2447, in wsgi_app\n",
      "    response = self.full_dispatch_request()\n",
      "  File \"C:\\ProgramData\\Anaconda3\\envs\\deepkeras\\lib\\site-packages\\flask\\app.py\", line 1952, in full_dispatch_request\n",
      "    rv = self.handle_user_exception(e)\n",
      "  File \"C:\\ProgramData\\Anaconda3\\envs\\deepkeras\\lib\\site-packages\\flask\\app.py\", line 1821, in handle_user_exception\n",
      "    reraise(exc_type, exc_value, tb)\n",
      "  File \"C:\\ProgramData\\Anaconda3\\envs\\deepkeras\\lib\\site-packages\\flask\\_compat.py\", line 39, in reraise\n",
      "    raise value\n",
      "  File \"C:\\ProgramData\\Anaconda3\\envs\\deepkeras\\lib\\site-packages\\flask\\app.py\", line 1950, in full_dispatch_request\n",
      "    rv = self.dispatch_request()\n",
      "  File \"C:\\ProgramData\\Anaconda3\\envs\\deepkeras\\lib\\site-packages\\flask\\app.py\", line 1936, in dispatch_request\n",
      "    return self.view_functions[rule.endpoint](**req.view_args)\n",
      "  File \"<ipython-input-11-0326dafe1a7e>\", line 42, in predictions\n",
      "    prediction = classifire.predict([[data]])[0]\n",
      "  File \"C:\\ProgramData\\Anaconda3\\envs\\deepkeras\\lib\\site-packages\\keras\\engine\\training.py\", line 1441, in predict\n",
      "    x, _, _ = self._standardize_user_data(x)\n",
      "  File \"C:\\ProgramData\\Anaconda3\\envs\\deepkeras\\lib\\site-packages\\keras\\engine\\training.py\", line 579, in _standardize_user_data\n",
      "    exception_prefix='input')\n",
      "  File \"C:\\ProgramData\\Anaconda3\\envs\\deepkeras\\lib\\site-packages\\keras\\engine\\training_utils.py\", line 145, in standardize_input_data\n",
      "    str(data_shape))\n",
      "ValueError: Error when checking input: expected dense_41_input to have shape (2,) but got array with shape (1,)\n",
      "127.0.0.1 - - [23/Nov/2020 18:08:04] \"\u001b[35m\u001b[1mPOST /predict HTTP/1.1\u001b[0m\" 500 -\n",
      "INFO:werkzeug:127.0.0.1 - - [23/Nov/2020 18:08:04] \"\u001b[35m\u001b[1mPOST /predict HTTP/1.1\u001b[0m\" 500 -\n"
     ]
    },
    {
     "name": "stdout",
     "output_type": "stream",
     "text": [
      "\n"
     ]
    }
   ],
   "source": [
    "import numpy\n",
    "from flask import Flask\n",
    "from flask import request\n",
    "from keras.layers import Dense,Dropout,Flatten,MaxPooling2D,Convolution2D,Activation\n",
    "from keras.models import Sequential\n",
    "from tensorflow.python.keras.backend import set_session\n",
    "from keras.models import load_model\n",
    "from keras.wrappers.scikit_learn import KerasClassifier\n",
    "import matplotlib.pyplot as plt\n",
    "import matplotlib.image as mpimg\n",
    "import tensorflow \n",
    "from io import BytesIO\n",
    "\n",
    "app = Flask(__name__)\n",
    "\n",
    "global graph\n",
    "graph = tensorflow.get_default_graph()\n",
    "sess = tensorflow.Session()\n",
    "\n",
    "def larger_model():\n",
    "        model = Sequential()\n",
    "        model.add(Dense(64,input_dim=2,activation='relu'))\n",
    "        model.add(Dense(256,activation='relu'))\n",
    "        model.add(Dropout(0.2))\n",
    "        model.add(Dense(128,activation='relu'))\n",
    "        model.add(Dense(1,activation='sigmoid'))\n",
    "\n",
    "        model.compile(loss='binary_crossentropy',optimizer='adam',metrics=['accuracy'])\n",
    "        return model\n",
    "\n",
    "#load model\n",
    "classifire = larger_model()  \n",
    "set_session(sess)\n",
    "classifire.load_weights('evaluate_88.h5') \n",
    "\n",
    "@app.route(\"/predict\",methods =['POST'])\n",
    "def predictions(): \n",
    "    with graph.as_default():\n",
    "                 set_session(sess)\n",
    "                 data = request.args.get('input', '') \n",
    "                 print(data)\n",
    "                 prediction = classifire.predict([[data]])[0]          \n",
    "    return str(prediction[0])\n",
    "\n",
    "if __name__ == '__main__':\n",
    "    app.run(debug=False, port=5003)"
   ]
  },
  {
   "cell_type": "code",
   "execution_count": null,
   "metadata": {},
   "outputs": [],
   "source": []
  },
  {
   "cell_type": "code",
   "execution_count": null,
   "metadata": {},
   "outputs": [],
   "source": []
  }
 ],
 "metadata": {
  "kernelspec": {
   "display_name": "Python 3",
   "language": "python",
   "name": "python3"
  },
  "language_info": {
   "codemirror_mode": {
    "name": "ipython",
    "version": 3
   },
   "file_extension": ".py",
   "mimetype": "text/x-python",
   "name": "python",
   "nbconvert_exporter": "python",
   "pygments_lexer": "ipython3",
   "version": "3.7.1"
  }
 },
 "nbformat": 4,
 "nbformat_minor": 4
}
